Workbook

Sheet Read Me
B2: UrbanCart Sales & Customer Intelligence — Workbook Guide
B4: How this workbook is organized
B5: Dashboard | C5: KPI summary, charts, and business-question tables — start here.
B6: Orders | C6: One row per order, with revenue/cost roll-ups pulled from Order Items.
B7: OrderItems | C7: One row per product sold within an order (the most granular data).
B8: Customers | C8: One row per customer, with total orders & spend roll-ups.
B9: Products | C9: One row per product, with units sold & margin roll-ups.
B10: Stores | C10: One row per store (plus the Online store), with revenue roll-ups.
B12: How the numbers work
B13: Net Revenue | C13: Quantity × Unit Price × (1 − Discount%), counted only on Delivered orders.
B14: Gross Profit | C14: Net Revenue minus (Quantity × Unit Cost).
B15: Everything is a live formula | C15: Every summary number recalculates automatically if you edit the raw data.

Sheet Dashboard
B2: UrbanCart — Sales & Customer Intelligence Dashboard
B3: Jan 2024 – Dec 2025 | Figures reflect Delivered orders only, net of discounts
B6: Total Net Revenue | F6: Delivered Orders | J6: Avg Order Value | N6: Repeat Purchase Rate | R6: Return Rate | V6: Gross Margin
B7: =SUMIF(Orders!$G$2:$G$3525,"Delivered",Orders!$K$2:$K$3525) -> 10243322 | F7: =COUNTIF(Orders!$G$2:$G$3525,"Delivered") -> 2500 | J7: =B7/F7 -> 4097.329 | N7: =COUNTIF(Customers!$M$2:$M$901,"Repeat")/COUNTIF(Customers!$J$2:$J$901,">0") -> 0.72893258 | R7: =COUNTIF(Orders!$G$2:$G$3525,"Returned")/COUNTA(Orders!$A$2:$A$3525) -> 0.14954597 | V7: =(SUMIF(Orders!$G$2:$G$3525,"Delivered",Orders!$M$2:$M$3525))/B7 -> 0.32626538
B10: Monthly Revenue Trend
B11: Month | C11: Net Revenue
B12: =TEXT(DATE(2024,1,1),"mmm yyyy") -> Jan 2024 | C12: =SUMIFS(Orders!$K$2:$K$3525,Orders!$D$2:$D$3525,">="&DATE(2024,1,1),Orders!$D$2:$D$3525,"<"&DATE(2024,2,1),Orders!$G$2:$G$3525,"Delivered") -> 111981.7
B13: =TEXT(DATE(2024,2,1),"mmm yyyy") -> Feb 2024 | C13: =SUMIFS(Orders!$K$2:$K$3525,Orders!$D$2:$D$3525,">="&DATE(2024,2,1),Orders!$D$2:$D$3525,"<"&DATE(2024,3,1),Orders!$G$2:$G$3525,"Delivered") -> 194610.9
B14: =TEXT(DATE(2024,3,1),"mmm yyyy") -> Mar 2024 | C14: =SUMIFS(Orders!$K$2:$K$3525,Orders!$D$2:$D$3525,">="&DATE(2024,3,1),Orders!$D$2:$D$3525,"<"&DATE(2024,4,1),Orders!$G$2:$G$3525,"Delivered") -> 220646
B15: =TEXT(DATE(2024,4,1),"mmm yyyy") -> Apr 2024 | C15: =SUMIFS(Orders!$K$2:$K$3525,Orders!$D$2:$D$3525,">="&DATE(2024,4,1),Orders!$D$2:$D$3525,"<"&DATE(2024,5,1),Orders!$G$2:$G$3525,"Delivered") -> 228044.1
B16: =TEXT(DATE(2024,5,1),"mmm yyyy") -> May 2024 | C16: =SUMIFS(Orders!$K$2:$K$3525,Orders!$D$2:$D$3525,">="&DATE(2024,5,1),Orders!$D$2:$D$3525,"<"&DATE(2024,6,1),Orders!$G$2:$G$3525,"Delivered") -> 229956.6
B17: =TEXT(DATE(2024,6,1),"mmm yyyy") -> Jun 2024 | C17: =SUMIFS(Orders!$K$2:$K$3525,Orders!$D$2:$D$3525,">="&DATE(2024,6,1),Orders!$D$2:$D$3525,"<"&DATE(2024,7,1),Orders!$G$2:$G$3525,"Delivered") -> 183298.95
B18: =TEXT(DATE(2024,7,1),"mmm yyyy") -> Jul 2024 | C18: =SUMIFS(Orders!$K$2:$K$3525,Orders!$D$2:$D$3525,">="&DATE(2024,7,1),Orders!$D$2:$D$3525,"<"&DATE(2024,8,1),Orders!$G$2:$G$3525,"Delivered") -> 328152.05
B19: =TEXT(DATE(2024,8,1),"mmm yyyy") -> Aug 2024 | C19: =SUMIFS(Orders!$K$2:$K$3525,Orders!$D$2:$D$3525,">="&DATE(2024,8,1),Orders!$D$2:$D$3525,"<"&DATE(2024,9,1),Orders!$G$2:$G$3525,"Delivered") -> 207433.7
B20: =TEXT(DATE(2024,9,1),"mmm yyyy") -> Sep 2024 | C20: =SUMIFS(Orders!$K$2:$K$3525,Orders!$D$2:$D$3525,">="&DATE(2024,9,1),Orders!$D$2:$D$3525,"<"&DATE(2024,10,1),Orders!$G$2:$G$3525,"Delivered") -> 223238.45
B21: =TEXT(DATE(2024,10,1),"mmm yyyy") -> Oct 2024 | C21: =SUMIFS(Orders!$K$2:$K$3525,Orders!$D$2:$D$3525,">="&DATE(2024,10,1),Orders!$D$2:$D$3525,"<"&DATE(2024,11,1),Orders!$G$2:$G$3525,"Delivered") -> 618031.55
B22: =TEXT(DATE(2024,11,1),"mmm yyyy") -> Nov 2024 | C22: =SUMIFS(Orders!$K$2:$K$3525,Orders!$D$2:$D$3525,">="&DATE(2024,11,1),Orders!$D$2:$D$3525,"<"&DATE(2024,12,1),Orders!$G$2:$G$3525,"Delivered") -> 590721
B23: =TEXT(DATE(2024,12,1),"mmm yyyy") -> Dec 2024 | C23: =SUMIFS(Orders!$K$2:$K$3525,Orders!$D$2:$D$3525,">="&DATE(2024,12,1),Orders!$D$2:$D$3525,"<"&DATE(2025,1,1),Orders!$G$2:$G$3525,"Delivered") -> 596365.7
B24: =TEXT(DATE(2025,1,1),"mmm yyyy") -> Jan 2025 | C24: =SUMIFS(Orders!$K$2:$K$3525,Orders!$D$2:$D$3525,">="&DATE(2025,1,1),Orders!$D$2:$D$3525,"<"&DATE(2025,2,1),Orders!$G$2:$G$3525,"Delivered") -> 224691.8
B25: =TEXT(DATE(2025,2,1),"mmm yyyy") -> Feb 2025 | C25: =SUMIFS(Orders!$K$2:$K$3525,Orders!$D$2:$D$3525,">="&DATE(2025,2,1),Orders!$D$2:$D$3525,"<"&DATE(2025,3,1),Orders!$G$2:$G$3525,"Delivered") -> 193985.4
B26: =TEXT(DATE(2025,3,1),"mmm yyyy") -> Mar 2025 | C26: =SUMIFS(Orders!$K$2:$K$3525,Orders!$D$2:$D$3525,">="&DATE(2025,3,1),Orders!$D$2:$D$3525,"<"&DATE(2025,4,1),Orders!$G$2:$G$3525,"Delivered") -> 349724.1
B27: =TEXT(DATE(2025,4,1),"mmm yyyy") -> Apr 2025 | C27: =SUMIFS(Orders!$K$2:$K$3525,Orders!$D$2:$D$3525,">="&DATE(2025,4,1),Orders!$D$2:$D$3525,"<"&DATE(2025,5,1),Orders!$G$2:$G$3525,"Delivered") -> 307793.45
B28: =TEXT(DATE(2025,5,1),"mmm yyyy") -> May 2025 | C28: =SUMIFS(Orders!$K$2:$K$3525,Orders!$D$2:$D$3525,">="&DATE(2025,5,1),Orders!$D$2:$D$3525,"<"&DATE(2025,6,1),Orders!$G$2:$G$3525,"Delivered") -> 385380.4
B29: =TEXT(DATE(2025,6,1),"mmm yyyy") -> Jun 2025 | C29: =SUMIFS(Orders!$K$2:$K$3525,Orders!$D$2:$D$3525,">="&DATE(2025,6,1),Orders!$D$2:$D$3525,"<"&DATE(2025,7,1),Orders!$G$2:$G$3525,"Delivered") -> 300685.75
B30: =TEXT(DATE(2025,7,1),"mmm yyyy") -> Jul 2025 | C30: =SUMIFS(Orders!$K$2:$K$3525,Orders!$D$2:$D$3525,">="&DATE(2025,7,1),Orders!$D$2:$D$3525,"<"&DATE(2025,8,1),Orders!$G$2:$G$3525,"Delivered") -> 553687.3
B31: =TEXT(DATE(2025,8,1),"mmm yyyy") -> Aug 2025 | C31: =SUMIFS(Orders!$K$2:$K$3525,Orders!$D$2:$D$3525,">="&DATE(2025,8,1),Orders!$D$2:$D$3525,"<"&DATE(2025,9,1),Orders!$G$2:$G$3525,"Delivered") -> 434891.55
B32: =TEXT(DATE(2025,9,1),"mmm yyyy") -> Sep 2025 | C32: =SUMIFS(Orders!$K$2:$K$3525,Orders!$D$2:$D$3525,">="&DATE(2025,9,1),Orders!$D$2:$D$3525,"<"&DATE(2025,10,1),Orders!$G$2:$G$3525,"Delivered") -> 472454.15
B33: =TEXT(DATE(2025,10,1),"mmm yyyy") -> Oct 2025 | C33: =SUMIFS(Orders!$K$2:$K$3525,Orders!$D$2:$D$3525,">="&DATE(2025,10,1),Orders!$D$2:$D$3525,"<"&DATE(2025,11,1),Orders!$G$2:$G$3525,"Delivered") -> 1011194.7
B34: =TEXT(DATE(2025,11,1),"mmm yyyy") -> Nov 2025 | C34: =SUMIFS(Orders!$K$2:$K$3525,Orders!$D$2:$D$3525,">="&DATE(2025,11,1),Orders!$D$2:$D$3525,"<"&DATE(2025,12,1),Orders!$G$2:$G$3525,"Delivered") -> 1137930.4
B35: =TEXT(DATE(2025,12,1),"mmm yyyy") -> Dec 2025 | C35: =SUMIFS(Orders!$K$2:$K$3525,Orders!$D$2:$D$3525,">="&DATE(2025,12,1),Orders!$D$2:$D$3525,"<"&DATE(2026,1,1),Orders!$G$2:$G$3525,"Delivered") -> 1138422.8
B38: Revenue & Margin by Category
B39: Category | C39: Net Revenue | D39: Gross Profit | E39: Margin %
B40: Beauty | C40: =SUMIF(Products!$C$2:$C$181,B40,Products!$H$2:$H$181) -> 871589.2 | D40: =SUMIF(Products!$C$2:$C$181,B40,Products!$I$2:$I$181) -> 287329.97 | E40: =IF(C40=0,0,D40/C40) -> 0.32966215
B41: Books & Stationery | C41: =SUMIF(Products!$C$2:$C$181,B41,Products!$H$2:$H$181) -> 449198.65 | D41: =SUMIF(Products!$C$2:$C$181,B41,Products!$I$2:$I$181) -> 147763 | E41: =IF(C41=0,0,D41/C41) -> 0.32894801
B42: Electronics | C42: =SUMIF(Products!$C$2:$C$181,B42,Products!$H$2:$H$181) -> 2711143.3 | D42: =SUMIF(Products!$C$2:$C$181,B42,Products!$I$2:$I$181) -> 871694.42 | E42: =IF(C42=0,0,D42/C42) -> 0.32152281
B43: Fashion | C43: =SUMIF(Products!$C$2:$C$181,B43,Products!$H$2:$H$181) -> 1440914.6 | D43: =SUMIF(Products!$C$2:$C$181,B43,Products!$I$2:$I$181) -> 490341.17 | E43: =IF(C43=0,0,D43/C43) -> 0.34029855
B44: Home & Kitchen | C44: =SUMIF(Products!$C$2:$C$181,B44,Products!$H$2:$H$181) -> 2474846.6 | D44: =SUMIF(Products!$C$2:$C$181,B44,Products!$I$2:$I$181) -> 822121.92 | E44: =IF(C44=0,0,D44/C44) -> 0.33219106
B45: Sports & Fitness | C45: =SUMIF(Products!$C$2:$C$181,B45,Products!$H$2:$H$181) -> 2295630 | D45: =SUMIF(Products!$C$2:$C$181,B45,Products!$I$2:$I$181) -> 722790.98 | E45: =IF(C45=0,0,D45/C45) -> 0.31485518
B48: Revenue by Region
B49: Region | C49: Orders | D49: Net Revenue
...

Sheet Stores
A1: store_id | B1: store_name | C1: city | D1: region | E1: total_orders | F1: net_revenue
A2: 1 | B2: UrbanCart Delhi Store | C2: Delhi | D2: North | E2: =COUNTIFS(Orders!$C$2:$C$3525,A2,Orders!$G$2:$G$3525,"Delivered") -> 42 | F2: =SUMIFS(Orders!$K$2:$K$3525,Orders!$C$2:$C$3525,A2,Orders!$G$2:$G$3525,"Delivered") -> 178005.5
A3: 2 | B3: UrbanCart Chandigarh Store | C3: Chandigarh | D3: North | E3: =COUNTIFS(Orders!$C$2:$C$3525,A3,Orders!$G$2:$G$3525,"Delivered") -> 35 | F3: =SUMIFS(Orders!$K$2:$K$3525,Orders!$C$2:$C$3525,A3,Orders!$G$2:$G$3525,"Delivered") -> 145523
A4: 3 | B4: UrbanCart Lucknow Store | C4: Lucknow | D4: North | E4: =COUNTIFS(Orders!$C$2:$C$3525,A4,Orders!$G$2:$G$3525,"Delivered") -> 50 | F4: =SUMIFS(Orders!$K$2:$K$3525,Orders!$C$2:$C$3525,A4,Orders!$G$2:$G$3525,"Delivered") -> 226124.75
A5: 4 | B5: UrbanCart Jaipur Store | C5: Jaipur | D5: North | E5: =COUNTIFS(Orders!$C$2:$C$3525,A5,Orders!$G$2:$G$3525,"Delivered") -> 47 | F5: =SUMIFS(Orders!$K$2:$K$3525,Orders!$C$2:$C$3525,A5,Orders!$G$2:$G$3525,"Delivered") -> 215463.8
A6: 5 | B6: UrbanCart Bengaluru Store | C6: Bengaluru | D6: South | E6: =COUNTIFS(Orders!$C$2:$C$3525,A6,Orders!$G$2:$G$3525,"Delivered") -> 43 | F6: =SUMIFS(Orders!$K$2:$K$3525,Orders!$C$2:$C$3525,A6,Orders!$G$2:$G$3525,"Delivered") -> 172326.4
A7: 6 | B7: UrbanCart Chennai Store | C7: Chennai | D7: South | E7: =COUNTIFS(Orders!$C$2:$C$3525,A7,Orders!$G$2:$G$3525,"Delivered") -> 44 | F7: =SUMIFS(Orders!$K$2:$K$3525,Orders!$C$2:$C$3525,A7,Orders!$G$2:$G$3525,"Delivered") -> 182870.85
A8: 7 | B8: UrbanCart Hyderabad Store | C8: Hyderabad | D8: South | E8: =COUNTIFS(Orders!$C$2:$C$3525,A8,Orders!$G$2:$G$3525,"Delivered") -> 43 | F8: =SUMIFS(Orders!$K$2:$K$3525,Orders!$C$2:$C$3525,A8,Orders!$G$2:$G$3525,"Delivered") -> 180927.95
A9: 8 | B9: UrbanCart Kochi Store | C9: Kochi | D9: South | E9: =COUNTIFS(Orders!$C$2:$C$3525,A9,Orders!$G$2:$G$3525,"Delivered") -> 50 | F9: =SUMIFS(Orders!$K$2:$K$3525,Orders!$C$2:$C$3525,A9,Orders!$G$2:$G$3525,"Delivered") -> 186958.5
A10: 9 | B10: UrbanCart Mumbai Store | C10: Mumbai | D10: West | E10: =COUNTIFS(Orders!$C$2:$C$3525,A10,Orders!$G$2:$G$3525,"Delivered") -> 37 | F10: =SUMIFS(Orders!$K$2:$K$3525,Orders!$C$2:$C$3525,A10,Orders!$G$2:$G$3525,"Delivered") -> 153401.4
A11: 10 | B11: UrbanCart Pune Store | C11: Pune | D11: West | E11: =COUNTIFS(Orders!$C$2:$C$3525,A11,Orders!$G$2:$G$3525,"Delivered") -> 39 | F11: =SUMIFS(Orders!$K$2:$K$3525,Orders!$C$2:$C$3525,A11,Orders!$G$2:$G$3525,"Delivered") -> 126517.55
A12: 11 | B12: UrbanCart Ahmedabad Store | C12: Ahmedabad | D12: West | E12: =COUNTIFS(Orders!$C$2:$C$3525,A12,Orders!$G$2:$G$3525,"Delivered") -> 40 | F12: =SUMIFS(Orders!$K$2:$K$3525,Orders!$C$2:$C$3525,A12,Orders!$G$2:$G$3525,"Delivered") -> 150803.55
A13: 12 | B13: UrbanCart Surat Store | C13: Surat | D13: West | E13: =COUNTIFS(Orders!$C$2:$C$3525,A13,Orders!$G$2:$G$3525,"Delivered") -> 39 | F13: =SUMIFS(Orders!$K$2:$K$3525,Orders!$C$2:$C$3525,A13,Orders!$G$2:$G$3525,"Delivered") -> 153395.95
... A18: 17 | B18: UrbanCart Online | C18: Online | D18: Online | E18: =COUNTIFS(Orders!$C$2:$C$3525,A18,Orders!$G$2:$G$3525,"Delivered") -> 1815 | F18: =SUMIFS(Orders!$K$2:$K$3525,Orders!$C$2:$C$3525,A18,Orders!$G$2:$G$3525,"Delivered") -> 7370641

Sheet Products
A1: product_id | B1: product_name | C1: category | D1: unit_price | E1: unit_cost | F1: supplier | G1: units_sold | H1: net_revenue | I1: gross_profit | J1: margin_pct
A2: 1 | B2: Wireless Earbuds - Model 1 | C2: Electronics | D2: 2759 | E2: 2042.05 | F2: Rodriguez, Figueroa and Sanchez | G2: =SUMIFS(OrderItems!$D$2:$D$6683,OrderItems!$C$2:$C$6683,A2,OrderItems!$I$2:$I$6683,"Delivered") -> 32 | H2: =SUMIFS(OrderItems!$J$2:$J$6683,OrderItems!$C$2:$C$6683,A2,OrderItems!$I$2:$I$6683,"Delivered") -> 85666.95 | I2: =SUMIFS(OrderItems!$L$2:$L$6683,OrderItems!$C$2:$C$6683,A2,OrderItems!$I$2:$I$6683,"Delivered") -> 20321.35 | J2: =IF(H2=0,0,I2/H2) -> 0.23721342
A3: 2 | B3: Wireless Earbuds - Model 2 | C3: Electronics | D3: 4619 | E3: 3093.49 | F3: Doyle Ltd | G3: =SUMIFS(OrderItems!$D$2:$D$6683,OrderItems!$C$2:$C$6683,A3,OrderItems!$I$2:$I$6683,"Delivered") -> 25 | H3: =SUMIFS(OrderItems!$J$2:$J$6683,OrderItems!$C$2:$C$6683,A3,OrderItems!$I$2:$I$6683,"Delivered") -> 114320.25 | I3: =SUMIFS(OrderItems!$L$2:$L$6683,OrderItems!$C$2:$C$6683,A3,OrderItems!$I$2:$I$6683,"Delivered") -> 36983 | J3: =IF(H3=0,0,I3/H3) -> 0.32350349
A4: 3 | B4: Wireless Earbuds - Model 3 | C4: Electronics | D4: 1619 | E4: 940.96 | F4: Mcclain, Miller and Henderson | G4: =SUMIFS(OrderItems!$D$2:$D$6683,OrderItems!$C$2:$C$6683,A4,OrderItems!$I$2:$I$6683,"Delivered") -> 30 | H4: =SUMIFS(OrderItems!$J$2:$J$6683,OrderItems!$C$2:$C$6683,A4,OrderItems!$I$2:$I$6683,"Delivered") -> 47922.4 | I4: =SUMIFS(OrderItems!$L$2:$L$6683,OrderItems!$C$2:$C$6683,A4,OrderItems!$I$2:$I$6683,"Delivered") -> 19693.6 | J4: =IF(H4=0,0,I4/H4) -> 0.4109477
A5: 4 | B5: Bluetooth Speaker - Model 1 | C5: Electronics | D5: 1109 | E5: 802.07 | F5: Davis and Sons | G5: =SUMIFS(OrderItems!$D$2:$D$6683,OrderItems!$C$2:$C$6683,A5,OrderItems!$I$2:$I$6683,"Delivered") -> 21 | H5: =SUMIFS(OrderItems!$J$2:$J$6683,OrderItems!$C$2:$C$6683,A5,OrderItems!$I$2:$I$6683,"Delivered") -> 22679.05 | I5: =SUMIFS(OrderItems!$L$2:$L$6683,OrderItems!$C$2:$C$6683,A5,OrderItems!$I$2:$I$6683,"Delivered") -> 5835.58 | J5: =IF(H5=0,0,I5/H5) -> 0.25731148
A6: 5 | B6: Bluetooth Speaker - Model 2 | C6: Electronics | D6: 3939 | E6: 2724.27 | F6: Guzman, Hoffman and Baldwin | G6: =SUMIFS(OrderItems!$D$2:$D$6683,OrderItems!$C$2:$C$6683,A6,OrderItems!$I$2:$I$6683,"Delivered") -> 30 | H6: =SUMIFS(OrderItems!$J$2:$J$6683,OrderItems!$C$2:$C$6683,A6,OrderItems!$I$2:$I$6683,"Delivered") -> 114231 | I6: =SUMIFS(OrderItems!$L$2:$L$6683,OrderItems!$C$2:$C$6683,A6,OrderItems!$I$2:$I$6683,"Delivered") -> 32502.9 | J6: =IF(H6=0,0,I6/H6) -> 0.2845366
A7: 6 | B7: Bluetooth Speaker - Model 3 | C7: Electronics | D7: 919 | E7: 683.72 | F7: Gardner, Robinson and Lawrence | G7: =SUMIFS(OrderItems!$D$2:$D$6683,OrderItems!$C$2:$C$6683,A7,OrderItems!$I$2:$I$6683,"Delivered") -> 33 | H7: =SUMIFS(OrderItems!$J$2:$J$6683,OrderItems!$C$2:$C$6683,A7,OrderItems!$I$2:$I$6683,"Delivered") -> 29729.65 | I7: =SUMIFS(OrderItems!$L$2:$L$6683,OrderItems!$C$2:$C$6683,A7,OrderItems!$I$2:$I$6683,"Delivered") -> 7166.89 | J7: =IF(H7=0,0,I7/H7) -> 0.24106876
A8: 7 | B8: Smartwatch - Model 1 | C8: Electronics | D8: 5139 | E8: 3044.69 | F8: Blake and Sons | G8: =SUMIFS(OrderItems!$D$2:$D$6683,OrderItems!$C$2:$C$6683,A8,OrderItems!$I$2:$I$6683,"Delivered") -> 35 | H8: =SUMIFS(OrderItems!$J$2:$J$6683,OrderItems!$C$2:$C$6683,A8,OrderItems!$I$2:$I$6683,"Delivered") -> 171385.65 | I8: =SUMIFS(OrderItems!$L$2:$L$6683,OrderItems!$C$2:$C$6683,A8,OrderItems!$I$2:$I$6683,"Delivered") -> 64821.5 | J8: =IF(H8=0,0,I8/H8) -> 0.37822011
A9: 8 | B9: Smartwatch - Model 2 | C9: Electronics | D9: 1759 | E9: 1031.97 | F9: Henderson, Ramirez and Lewis | G9: =SUMIFS(OrderItems!$D$2:$D$6683,OrderItems!$C$2:$C$6683,A9,OrderItems!$I$2:$I$6683,"Delivered") -> 37 | H9: =SUMIFS(OrderItems!$J$2:$J$6683,OrderItems!$C$2:$C$6683,A9,OrderItems!$I$2:$I$6683,"Delivered") -> 63851.7 | I9: =SUMIFS(OrderItems!$L$2:$L$6683,OrderItems!$C$2:$C$6683,A9,OrderItems!$I$2:$I$6683,"Delivered") -> 25668.81 | J9: =IF(H9=0,0,I9/H9) -> 0.40200668
A10: 9 | B10: Smartwatch - Model 3 | C10: Electronics | D10: 2389 | E10: 1564.68 | F10: Garcia-James | G10: =SUMIFS(OrderItems!$D$2:$D$6683,OrderItems!$C$2:$C$6683,A10,OrderItems!$I$2:$I$6683,"Delivered") -> 27 | H10: =SUMIFS(OrderItems!$J$2:$J$6683,OrderItems!$C$2:$C$6683,A10,OrderItems!$I$2:$I$6683,"Delivered") -> 60919.5 | I10: =SUMIFS(OrderItems!$L$2:$L$6683,OrderItems!$C$2:$C$6683,A10,OrderItems!$I$2:$I$6683,"Delivered") -> 18673.14 | J10: =IF(H10=0,0,I10/H10) -> 0.30652156
A11: 10 | B11: Laptop Bag - Model 1 | C11: Electronics | D11: 3059 | E11: 1860.62 | F11: Abbott-Munoz | G11: =SUMIFS(OrderItems!$D$2:$D$6683,OrderItems!$C$2:$C$6683,A11,OrderItems!$I$2:$I$6683,"Delivered") -> 29 | H11: =SUMIFS(OrderItems!$J$2:$J$6683,OrderItems!$C$2:$C$6683,A11,OrderItems!$I$2:$I$6683,"Delivered") -> 84428.4 | I11: =SUMIFS(OrderItems!$L$2:$L$6683,OrderItems!$C$2:$C$6683,A11,OrderItems!$I$2:$I$6683,"Delivered") -> 30470.42 | J11: =IF(H11=0,0,I11/H11) -> 0.36090249
A12: 11 | B12: Laptop Bag - Model 2 | C12: Electronics | D12: 3989 | E12: 2305.24 | F12: Blair PLC | G12: =SUMIFS(OrderItems!$D$2:$D$6683,OrderItems!$C$2:$C$6683,A12,OrderItems!$I$2:$I$6683,"Delivered") -> 33 | H12: =SUMIFS(OrderItems!$J$2:$J$6683,OrderItems!$C$2:$C$6683,A12,OrderItems!$I$2:$I$6683,"Delivered") -> 127049.65 | I12: =SUMIFS(OrderItems!$L$2:$L$6683,OrderItems!$C$2:$C$6683,A12,OrderItems!$I$2:$I$6683,"Delivered") -> 50976.73 | J12: =IF(H12=0,0,I12/H12) -> 0.40123471
A13: 12 | B13: Laptop Bag - Model 3 | C13: Electronics | D13: 2329 | E13: 1451.6 | F13: Dudley Group | G13: =SUMIFS(OrderItems!$D$2:$D$6683,OrderItems!$C$2:$C$6683,A13,OrderItems!$I$2:$I$6683,"Delivered") -> 28 | H13: =SUMIFS(OrderItems!$J$2:$J$6683,OrderItems!$C$2:$C$6683,A13,OrderItems!$I$2:$I$6683,"Delivered") -> 62533.65 | I13: =SUMIFS(OrderItems!$L$2:$L$6683,OrderItems!$C$2:$C$6683,A13,OrderItems!$I$2:$I$6683,"Delivered") -> 21888.85 | J13: =IF(H13=0,0,I13/H13) -> 0.35003314
... A181: 180 | B181: Desk Organizer - Model 3 | C181: Books & Stationery | D181: 859 | E181: 571.32 | F181: Howell and Sons | G181: =SUMIFS(OrderItems!$D$2:$D$6683,OrderItems!$C$2:$C$6683,A181,OrderItems!$I$2:$I$6683,"Delivered") -> 31 | H181: =SUMIFS(OrderItems!$J$2:$J$6683,OrderItems!$C$2:$C$6683,A181,OrderItems!$I$2:$I$6683,"Delivered") -> 25125.75 | I181: =SUMIFS(OrderItems!$L$2:$L$6683,OrderItems!$C$2:$C$6683,A181,OrderItems!$I$2:$I$6683,"Delivered") -> 7414.83 | J181: =IF(H181=0,0,I181/H181) -> 0.2951088

Sheet Customers
A1: customer_id | B1: customer_name | C1: email | D1: gender | E1: age | F1: city | G1: region | H1: signup_date | I1: customer_segment | J1: total_orders | K1: total_spend | L1: avg_order_value | M1: buyer_type
A2: 1 | B2: Kristy Robinson | C2: katie29@example.net | D2: Male | E2: 65 | F2: Jaipur | G2: North | H2: 44866 | I2: Regular | J2: =COUNTIFS(Orders!$B$2:$B$3525,A2,Orders!$G$2:$G$3525,"Delivered") -> 0 | K2: =SUMIFS(Orders!$K$2:$K$3525,Orders!$B$2:$B$3525,A2,Orders!$G$2:$G$3525,"Delivered") -> 0 | L2: =IF(J2=0,0,K2/J2) -> 0 | M2: =IF(J2>1,"Repeat","One-time") -> One-time
A3: 2 | B3: Paula Martin | C3: daniel04@example.net | D3: Male | E3: 65 | F3: Kochi | G3: South | H3: 45886 | I3: Regular | J3: =COUNTIFS(Orders!$B$2:$B$3525,A3,Orders!$G$2:$G$3525,"Delivered") -> 5 | K3: =SUMIFS(Orders!$K$2:$K$3525,Orders!$B$2:$B$3525,A3,Orders!$G$2:$G$3525,"Delivered") -> 27284.8 | L3: =IF(J3=0,0,K3/J3) -> 5456.96 | M3: =IF(J3>1,"Repeat","One-time") -> Repeat
A4: 3 | B4: Jennifer Espinoza | C4: vargasmaria@example.org | D4: Female | E4: 20 | F4: Lucknow | G4: North | H4: 45538 | I4: Regular | J4: =COUNTIFS(Orders!$B$2:$B$3525,A4,Orders!$G$2:$G$3525,"Delivered") -> 5 | K4: =SUMIFS(Orders!$K$2:$K$3525,Orders!$B$2:$B$3525,A4,Orders!$G$2:$G$3525,"Delivered") -> 13671.25 | L4: =IF(J4=0,0,K4/J4) -> 2734.25 | M4: =IF(J4>1,"Repeat","One-time") -> Repeat
A5: 4 | B5: Sarah Burke | C5: hoganashlee@example.org | D5: Male | E5: 50 | F5: Hyderabad | G5: South | H5: 44837 | I5: Premium | J5: =COUNTIFS(Orders!$B$2:$B$3525,A5,Orders!$G$2:$G$3525,"Delivered") -> 2 | K5: =SUMIFS(Orders!$K$2:$K$3525,Orders!$B$2:$B$3525,A5,Orders!$G$2:$G$3525,"Delivered") -> 11770.55 | L5: =IF(J5=0,0,K5/J5) -> 5885.275 | M5: =IF(J5>1,"Repeat","One-time") -> Repeat
A6: 5 | B6: Jacob Hunter | C6: alexander67@example.org | D6: Female | E6: 32 | F6: Hyderabad | G6: South | H6: 45135 | I6: Regular | J6: =COUNTIFS(Orders!$B$2:$B$3525,A6,Orders!$G$2:$G$3525,"Delivered") -> 1 | K6: =SUMIFS(Orders!$K$2:$K$3525,Orders!$B$2:$B$3525,A6,Orders!$G$2:$G$3525,"Delivered") -> 2597.05 | L6: =IF(J6=0,0,K6/J6) -> 2597.05 | M6: =IF(J6>1,"Repeat","One-time") -> One-time
A7: 6 | B7: Steven Stevens | C7: ryangross@example.net | D7: Male | E7: 28 | F7: Mumbai | G7: West | H7: 45241 | I7: Premium | J7: =COUNTIFS(Orders!$B$2:$B$3525,A7,Orders!$G$2:$G$3525,"Delivered") -> 1 | K7: =SUMIFS(Orders!$K$2:$K$3525,Orders!$B$2:$B$3525,A7,Orders!$G$2:$G$3525,"Delivered") -> 3448 | L7: =IF(J7=0,0,K7/J7) -> 3448 | M7: =IF(J7>1,"Repeat","One-time") -> One-time
A8: 7 | B8: Kimberly Webb | C8: lpetersen@example.com | D8: Female | E8: 27 | F8: Ahmedabad | G8: West | H8: 45041 | I8: Regular | J8: =COUNTIFS(Orders!$B$2:$B$3525,A8,Orders!$G$2:$G$3525,"Delivered") -> 0 | K8: =SUMIFS(Orders!$K$2:$K$3525,Orders!$B$2:$B$3525,A8,Orders!$G$2:$G$3525,"Delivered") -> 0 | L8: =IF(J8=0,0,K8/J8) -> 0 | M8: =IF(J8>1,"Repeat","One-time") -> One-time
A9: 8 | B9: Timothy Ramirez | C9: dsanchez@example.net | D9: Male | E9: 23 | F9: Ahmedabad | G9: West | H9: 45105 | I9: Regular | J9: =COUNTIFS(Orders!$B$2:$B$3525,A9,Orders!$G$2:$G$3525,"Delivered") -> 6 | K9: =SUMIFS(Orders!$K$2:$K$3525,Orders!$B$2:$B$3525,A9,Orders!$G$2:$G$3525,"Delivered") -> 15016.9 | L9: =IF(J9=0,0,K9/J9) -> 2502.8167 | M9: =IF(J9>1,"Repeat","One-time") -> Repeat
A10: 9 | B10: Allen Rosales | C10: tonykelly@example.com | D10: Female | E10: 56 | F10: Surat | G10: West | H10: 45456 | I10: Regular | J10: =COUNTIFS(Orders!$B$2:$B$3525,A10,Orders!$G$2:$G$3525,"Delivered") -> 8 | K10: =SUMIFS(Orders!$K$2:$K$3525,Orders!$B$2:$B$3525,A10,Orders!$G$2:$G$3525,"Delivered") -> 35314.25 | L10: =IF(J10=0,0,K10/J10) -> 4414.2812 | M10: =IF(J10>1,"Repeat","One-time") -> Repeat
A11: 10 | B11: Meredith Hill | C11: blackjames@example.org | D11: Female | E11: 52 | F11: Chandigarh | G11: North | H11: 45127 | I11: Regular | J11: =COUNTIFS(Orders!$B$2:$B$3525,A11,Orders!$G$2:$G$3525,"Delivered") -> 7 | K11: =SUMIFS(Orders!$K$2:$K$3525,Orders!$B$2:$B$3525,A11,Orders!$G$2:$G$3525,"Delivered") -> 38625.4 | L11: =IF(J11=0,0,K11/J11) -> 5517.9143 | M11: =IF(J11>1,"Repeat","One-time") -> Repeat
A12: 11 | B12: Peter Vaughn DDS | C12: bwest@example.org | D12: Male | E12: 53 | F12: Kolkata | G12: East | H12: 45590 | I12: Regular | J12: =COUNTIFS(Orders!$B$2:$B$3525,A12,Orders!$G$2:$G$3525,"Delivered") -> 0 | K12: =SUMIFS(Orders!$K$2:$K$3525,Orders!$B$2:$B$3525,A12,Orders!$G$2:$G$3525,"Delivered") -> 0 | L12: =IF(J12=0,0,K12/J12) -> 0 | M12: =IF(J12>1,"Repeat","One-time") -> One-time
A13: 12 | B13: David Beck | C13: thomas85@example.com | D13: Male | E13: 63 | F13: Surat | G13: West | H13: 45071 | I13: Regular | J13: =COUNTIFS(Orders!$B$2:$B$3525,A13,Orders!$G$2:$G$3525,"Delivered") -> 5 | K13: =SUMIFS(Orders!$K$2:$K$3525,Orders!$B$2:$B$3525,A13,Orders!$G$2:$G$3525,"Delivered") -> 16113.25 | L13: =IF(J13=0,0,K13/J13) -> 3222.65 | M13: =IF(J13>1,"Repeat","One-time") -> Repeat
... A901: 900 | B901: Robert Salas | C901: fclark@example.com | D901: Female | E901: 45 | F901: Bhubaneswar | G901: East | H901: 45112 | I901: New | J901: =COUNTIFS(Orders!$B$2:$B$3525,A901,Orders!$G$2:$G$3525,"Delivered") -> 2 | K901: =SUMIFS(Orders!$K$2:$K$3525,Orders!$B$2:$B$3525,A901,Orders!$G$2:$G$3525,"Delivered") -> 9313.35 | L901: =IF(J901=0,0,K901/J901) -> 4656.675 | M901: =IF(J901>1,"Repeat","One-time") -> Repeat

Sheet OrderItems
A1: order_item_id | B1: order_id | C1: product_id | D1: quantity | E1: unit_price | F1: discount_pct | G1: category | H1: unit_cost | I1: order_status | J1: line_net_revenue | K1: line_cost | L1: line_gross_profit
A2: 1 | B2: 1 | C2: 136 | D2: 1 | E2: 3299 | F2: 5 | G2: =INDEX(Products!$C$2:$C$181,MATCH(C2,Products!$A$2:$A$181,0)) -> Sports & Fitness | H2: =INDEX(Products!$E$2:$E$181,MATCH(C2,Products!$A$2:$A$181,0)) -> 2348.96 | I2: =INDEX(Orders!$G$2:$G$3525,MATCH(B2,Orders!$A$2:$A$3525,0)) -> Delivered | J2: =D2*E2*(1-F2/100) -> 3134.05 | K2: =D2*H2 -> 2348.96 | L2: =J2-K2 -> 785.09
A3: 2 | B3: 2 | C3: 106 | D3: 1 | E3: 1069 | F3: 0 | G3: =INDEX(Products!$C$2:$C$181,MATCH(C3,Products!$A$2:$A$181,0)) -> Beauty | H3: =INDEX(Products!$E$2:$E$181,MATCH(C3,Products!$A$2:$A$181,0)) -> 735.88 | I3: =INDEX(Orders!$G$2:$G$3525,MATCH(B3,Orders!$A$2:$A$3525,0)) -> Delivered | J3: =D3*E3*(1-F3/100) -> 1069 | K3: =D3*H3 -> 735.88 | L3: =J3-K3 -> 333.12
A4: 3 | B4: 3 | C4: 127 | D4: 1 | E4: 3449 | F4: 0 | G4: =INDEX(Products!$C$2:$C$181,MATCH(C4,Products!$A$2:$A$181,0)) -> Sports & Fitness | H4: =INDEX(Products!$E$2:$E$181,MATCH(C4,Products!$A$2:$A$181,0)) -> 2115.56 | I4: =INDEX(Orders!$G$2:$G$3525,MATCH(B4,Orders!$A$2:$A$3525,0)) -> Delivered | J4: =D4*E4*(1-F4/100) -> 3449 | K4: =D4*H4 -> 2115.56 | L4: =J4-K4 -> 1333.44
A5: 4 | B5: 4 | C5: 71 | D5: 1 | E5: 2909 | F5: 20 | G5: =INDEX(Products!$C$2:$C$181,MATCH(C5,Products!$A$2:$A$181,0)) -> Fashion | H5: =INDEX(Products!$E$2:$E$181,MATCH(C5,Products!$A$2:$A$181,0)) -> 1746.44 | I5: =INDEX(Orders!$G$2:$G$3525,MATCH(B5,Orders!$A$2:$A$3525,0)) -> Delivered | J5: =D5*E5*(1-F5/100) -> 2327.2 | K5: =D5*H5 -> 1746.44 | L5: =J5-K5 -> 580.76
A6: 5 | B6: 4 | C6: 129 | D6: 1 | E6: 3769 | F6: 5 | G6: =INDEX(Products!$C$2:$C$181,MATCH(C6,Products!$A$2:$A$181,0)) -> Sports & Fitness | H6: =INDEX(Products!$E$2:$E$181,MATCH(C6,Products!$A$2:$A$181,0)) -> 2597.62 | I6: =INDEX(Orders!$G$2:$G$3525,MATCH(B6,Orders!$A$2:$A$3525,0)) -> Delivered | J6: =D6*E6*(1-F6/100) -> 3580.55 | K6: =D6*H6 -> 2597.62 | L6: =J6-K6 -> 982.93
A7: 6 | B7: 4 | C7: 16 | D7: 3 | E7: 3969 | F7: 0 | G7: =INDEX(Products!$C$2:$C$181,MATCH(C7,Products!$A$2:$A$181,0)) -> Electronics | H7: =INDEX(Products!$E$2:$E$181,MATCH(C7,Products!$A$2:$A$181,0)) -> 2318.31 | I7: =INDEX(Orders!$G$2:$G$3525,MATCH(B7,Orders!$A$2:$A$3525,0)) -> Delivered | J7: =D7*E7*(1-F7/100) -> 11907 | K7: =D7*H7 -> 6954.93 | L7: =J7-K7 -> 4952.07
A8: 7 | B8: 5 | C8: 57 | D8: 1 | E8: 4689 | F8: 0 | G8: =INDEX(Products!$C$2:$C$181,MATCH(C8,Products!$A$2:$A$181,0)) -> Home & Kitchen | H8: =INDEX(Products!$E$2:$E$181,MATCH(C8,Products!$A$2:$A$181,0)) -> 3336.81 | I8: =INDEX(Orders!$G$2:$G$3525,MATCH(B8,Orders!$A$2:$A$3525,0)) -> Returned | J8: =D8*E8*(1-F8/100) -> 4689 | K8: =D8*H8 -> 3336.81 | L8: =J8-K8 -> 1352.19
A9: 8 | B9: 6 | C9: 51 | D9: 1 | E9: 549 | F9: 0 | G9: =INDEX(Products!$C$2:$C$181,MATCH(C9,Products!$A$2:$A$181,0)) -> Home & Kitchen | H9: =INDEX(Products!$E$2:$E$181,MATCH(C9,Products!$A$2:$A$181,0)) -> 371.83 | I9: =INDEX(Orders!$G$2:$G$3525,MATCH(B9,Orders!$A$2:$A$3525,0)) -> Delivered | J9: =D9*E9*(1-F9/100) -> 549 | K9: =D9*H9 -> 371.83 | L9: =J9-K9 -> 177.17
A10: 9 | B10: 6 | C10: 29 | D10: 1 | E10: 1269 | F10: 0 | G10: =INDEX(Products!$C$2:$C$181,MATCH(C10,Products!$A$2:$A$181,0)) -> Electronics | H10: =INDEX(Products!$E$2:$E$181,MATCH(C10,Products!$A$2:$A$181,0)) -> 747.69 | I10: =INDEX(Orders!$G$2:$G$3525,MATCH(B10,Orders!$A$2:$A$3525,0)) -> Delivered | J10: =D10*E10*(1-F10/100) -> 1269 | K10: =D10*H10 -> 747.69 | L10: =J10-K10 -> 521.31
A11: 10 | B11: 7 | C11: 54 | D11: 3 | E11: 2299 | F11: 5 | G11: =INDEX(Products!$C$2:$C$181,MATCH(C11,Products!$A$2:$A$181,0)) -> Home & Kitchen | H11: =INDEX(Products!$E$2:$E$181,MATCH(C11,Products!$A$2:$A$181,0)) -> 1611.85 | I11: =INDEX(Orders!$G$2:$G$3525,MATCH(B11,Orders!$A$2:$A$3525,0)) -> Cancelled | J11: =D11*E11*(1-F11/100) -> 6552.15 | K11: =D11*H11 -> 4835.55 | L11: =J11-K11 -> 1716.6
A12: 11 | B12: 7 | C12: 146 | D12: 1 | E12: 369 | F12: 0 | G12: =INDEX(Products!$C$2:$C$181,MATCH(C12,Products!$A$2:$A$181,0)) -> Sports & Fitness | H12: =INDEX(Products!$E$2:$E$181,MATCH(C12,Products!$A$2:$A$181,0)) -> 205.71 | I12: =INDEX(Orders!$G$2:$G$3525,MATCH(B12,Orders!$A$2:$A$3525,0)) -> Cancelled | J12: =D12*E12*(1-F12/100) -> 369 | K12: =D12*H12 -> 205.71 | L12: =J12-K12 -> 163.29
A13: 12 | B13: 8 | C13: 137 | D13: 1 | E13: 3509 | F13: 0 | G13: =INDEX(Products!$C$2:$C$181,MATCH(C13,Products!$A$2:$A$181,0)) -> Sports & Fitness | H13: =INDEX(Products!$E$2:$E$181,MATCH(C13,Products!$A$2:$A$181,0)) -> 2570.86 | I13: =INDEX(Orders!$G$2:$G$3525,MATCH(B13,Orders!$A$2:$A$3525,0)) -> Returned | J13: =D13*E13*(1-F13/100) -> 3509 | K13: =D13*H13 -> 2570.86 | L13: =J13-K13 -> 938.14
... A6683: 6682 | B6683: 3524 | C6683: 11 | D6683: 1 | E6683: 3989 | F6683: 5 | G6683: =INDEX(Products!$C$2:$C$181,MATCH(C6683,Products!$A$2:$A$181,0)) -> Electronics | H6683: =INDEX(Products!$E$2:$E$181,MATCH(C6683,Products!$A$2:$A$181,0)) -> 2305.24 | I6683: =INDEX(Orders!$G$2:$G$3525,MATCH(B6683,Orders!$A$2:$A$3525,0)) -> Delivered | J6683: =D6683*E6683*(1-F6683/100) -> 3789.55 | K6683: =D6683*H6683 -> 2305.24 | L6683: =J6683-K6683 -> 1484.31

Sheet Orders
A1: order_id | B1: customer_id | C1: store_id | D1: order_date | E1: channel | F1: payment_method | G1: order_status | H1: customer_segment | I1: customer_region | J1: store_region | K1: net_revenue | L1: cost | M1: gross_profit | N1: item_count
A2: 1 | B2: 2 | C2: 8 | D2: 45892 | E2: In-Store | F2: UPI | G2: Delivered | H2: =INDEX(Customers!$I$2:$I$901,MATCH(B2,Customers!$A$2:$A$901,0)) -> Regular | I2: =INDEX(Customers!$G$2:$G$901,MATCH(B2,Customers!$A$2:$A$901,0)) -> South | J2: =INDEX(Stores!$D$2:$D$18,MATCH(C2,Stores!$A$2:$A$18,0)) -> South | K2: =SUMIF(OrderItems!$B$2:$B$6683,A2,OrderItems!$J$2:$J$6683) -> 3134.05 | L2: =SUMIF(OrderItems!$B$2:$B$6683,A2,OrderItems!$K$2:$K$6683) -> 2348.96 | M2: =K2-L2 -> 785.09 | N2: =COUNTIF(OrderItems!$B$2:$B$6683,A2) -> 1
A3: 2 | B3: 2 | C3: 3 | D3: 45930 | E3: In-Store | F3: Cash on Delivery | G3: Delivered | H3: =INDEX(Customers!$I$2:$I$901,MATCH(B3,Customers!$A$2:$A$901,0)) -> Regular | I3: =INDEX(Customers!$G$2:$G$901,MATCH(B3,Customers!$A$2:$A$901,0)) -> South | J3: =INDEX(Stores!$D$2:$D$18,MATCH(C3,Stores!$A$2:$A$18,0)) -> North | K3: =SUMIF(OrderItems!$B$2:$B$6683,A3,OrderItems!$J$2:$J$6683) -> 1069 | L3: =SUMIF(OrderItems!$B$2:$B$6683,A3,OrderItems!$K$2:$K$6683) -> 735.88 | M3: =K3-L3 -> 333.12 | N3: =COUNTIF(OrderItems!$B$2:$B$6683,A3) -> 1
A4: 3 | B4: 2 | C4: 17 | D4: 45934 | E4: Online | F4: UPI | G4: Delivered | H4: =INDEX(Customers!$I$2:$I$901,MATCH(B4,Customers!$A$2:$A$901,0)) -> Regular | I4: =INDEX(Customers!$G$2:$G$901,MATCH(B4,Customers!$A$2:$A$901,0)) -> South | J4: =INDEX(Stores!$D$2:$D$18,MATCH(C4,Stores!$A$2:$A$18,0)) -> Online | K4: =SUMIF(OrderItems!$B$2:$B$6683,A4,OrderItems!$J$2:$J$6683) -> 3449 | L4: =SUMIF(OrderItems!$B$2:$B$6683,A4,OrderItems!$K$2:$K$6683) -> 2115.56 | M4: =K4-L4 -> 1333.44 | N4: =COUNTIF(OrderItems!$B$2:$B$6683,A4) -> 1
A5: 4 | B5: 2 | C5: 17 | D5: 45948 | E5: Online | F5: Credit Card | G5: Delivered | H5: =INDEX(Customers!$I$2:$I$901,MATCH(B5,Customers!$A$2:$A$901,0)) -> Regular | I5: =INDEX(Customers!$G$2:$G$901,MATCH(B5,Customers!$A$2:$A$901,0)) -> South | J5: =INDEX(Stores!$D$2:$D$18,MATCH(C5,Stores!$A$2:$A$18,0)) -> Online | K5: =SUMIF(OrderItems!$B$2:$B$6683,A5,OrderItems!$J$2:$J$6683) -> 17814.75 | L5: =SUMIF(OrderItems!$B$2:$B$6683,A5,OrderItems!$K$2:$K$6683) -> 11298.99 | M5: =K5-L5 -> 6515.76 | N5: =COUNTIF(OrderItems!$B$2:$B$6683,A5) -> 3
A6: 5 | B6: 2 | C6: 17 | D6: 45957 | E6: Online | F6: Cash on Delivery | G6: Returned | H6: =INDEX(Customers!$I$2:$I$901,MATCH(B6,Customers!$A$2:$A$901,0)) -> Regular | I6: =INDEX(Customers!$G$2:$G$901,MATCH(B6,Customers!$A$2:$A$901,0)) -> South | J6: =INDEX(Stores!$D$2:$D$18,MATCH(C6,Stores!$A$2:$A$18,0)) -> Online | K6: =SUMIF(OrderItems!$B$2:$B$6683,A6,OrderItems!$J$2:$J$6683) -> 4689 | L6: =SUMIF(OrderItems!$B$2:$B$6683,A6,OrderItems!$K$2:$K$6683) -> 3336.81 | M6: =K6-L6 -> 1352.19 | N6: =COUNTIF(OrderItems!$B$2:$B$6683,A6) -> 1
A7: 6 | B7: 2 | C7: 17 | D7: 45976 | E7: Online | F7: Cash on Delivery | G7: Delivered | H7: =INDEX(Customers!$I$2:$I$901,MATCH(B7,Customers!$A$2:$A$901,0)) -> Regular | I7: =INDEX(Customers!$G$2:$G$901,MATCH(B7,Customers!$A$2:$A$901,0)) -> South | J7: =INDEX(Stores!$D$2:$D$18,MATCH(C7,Stores!$A$2:$A$18,0)) -> Online | K7: =SUMIF(OrderItems!$B$2:$B$6683,A7,OrderItems!$J$2:$J$6683) -> 1818 | L7: =SUMIF(OrderItems!$B$2:$B$6683,A7,OrderItems!$K$2:$K$6683) -> 1119.52 | M7: =K7-L7 -> 698.48 | N7: =COUNTIF(OrderItems!$B$2:$B$6683,A7) -> 2
A8: 7 | B8: 2 | C8: 17 | D8: 46002 | E8: Online | F8: Credit Card | G8: Cancelled | H8: =INDEX(Customers!$I$2:$I$901,MATCH(B8,Customers!$A$2:$A$901,0)) -> Regular | I8: =INDEX(Customers!$G$2:$G$901,MATCH(B8,Customers!$A$2:$A$901,0)) -> South | J8: =INDEX(Stores!$D$2:$D$18,MATCH(C8,Stores!$A$2:$A$18,0)) -> Online | K8: =SUMIF(OrderItems!$B$2:$B$6683,A8,OrderItems!$J$2:$J$6683) -> 6921.15 | L8: =SUMIF(OrderItems!$B$2:$B$6683,A8,OrderItems!$K$2:$K$6683) -> 5041.26 | M8: =K8-L8 -> 1879.89 | N8: =COUNTIF(OrderItems!$B$2:$B$6683,A8) -> 2
A9: 8 | B9: 2 | C9: 6 | D9: 46011 | E9: In-Store | F9: Cash on Delivery | G9: Returned | H9: =INDEX(Customers!$I$2:$I$901,MATCH(B9,Customers!$A$2:$A$901,0)) -> Regular | I9: =INDEX(Customers!$G$2:$G$901,MATCH(B9,Customers!$A$2:$A$901,0)) -> South | J9: =INDEX(Stores!$D$2:$D$18,MATCH(C9,Stores!$A$2:$A$18,0)) -> South | K9: =SUMIF(OrderItems!$B$2:$B$6683,A9,OrderItems!$J$2:$J$6683) -> 3509 | L9: =SUMIF(OrderItems!$B$2:$B$6683,A9,OrderItems!$K$2:$K$6683) -> 2570.86 | M9: =K9-L9 -> 938.14 | N9: =COUNTIF(OrderItems!$B$2:$B$6683,A9) -> 1
A10: 9 | B10: 3 | C10: 17 | D10: 45597 | E10: Online | F10: Debit Card | G10: Delivered | H10: =INDEX(Customers!$I$2:$I$901,MATCH(B10,Customers!$A$2:$A$901,0)) -> Regular | I10: =INDEX(Customers!$G$2:$G$901,MATCH(B10,Customers!$A$2:$A$901,0)) -> North | J10: =INDEX(Stores!$D$2:$D$18,MATCH(C10,Stores!$A$2:$A$18,0)) -> Online | K10: =SUMIF(OrderItems!$B$2:$B$6683,A10,OrderItems!$J$2:$J$6683) -> 3789 | L10: =SUMIF(OrderItems!$B$2:$B$6683,A10,OrderItems!$K$2:$K$6683) -> 2806.84 | M10: =K10-L10 -> 982.16 | N10: =COUNTIF(OrderItems!$B$2:$B$6683,A10) -> 1
A11: 10 | B11: 3 | C11: 17 | D11: 45860 | E11: Online | F11: Credit Card | G11: Delivered | H11: =INDEX(Customers!$I$2:$I$901,MATCH(B11,Customers!$A$2:$A$901,0)) -> Regular | I11: =INDEX(Customers!$G$2:$G$901,MATCH(B11,Customers!$A$2:$A$901,0)) -> North | J11: =INDEX(Stores!$D$2:$D$18,MATCH(C11,Stores!$A$2:$A$18,0)) -> Online | K11: =SUMIF(OrderItems!$B$2:$B$6683,A11,OrderItems!$J$2:$J$6683) -> 1000.2 | L11: =SUMIF(OrderItems!$B$2:$B$6683,A11,OrderItems!$K$2:$K$6683) -> 704.06 | M11: =K11-L11 -> 296.14 | N11: =COUNTIF(OrderItems!$B$2:$B$6683,A11) -> 2
A12: 11 | B12: 3 | C12: 17 | D12: 45888 | E12: Online | F12: Cash on Delivery | G12: Delivered | H12: =INDEX(Customers!$I$2:$I$901,MATCH(B12,Customers!$A$2:$A$901,0)) -> Regular | I12: =INDEX(Customers!$G$2:$G$901,MATCH(B12,Customers!$A$2:$A$901,0)) -> North | J12: =INDEX(Stores!$D$2:$D$18,MATCH(C12,Stores!$A$2:$A$18,0)) -> Online | K12: =SUMIF(OrderItems!$B$2:$B$6683,A12,OrderItems!$J$2:$J$6683) -> 149 | L12: =SUMIF(OrderItems!$B$2:$B$6683,A12,OrderItems!$K$2:$K$6683) -> 83.16 | M12: =K12-L12 -> 65.84 | N12: =COUNTIF(OrderItems!$B$2:$B$6683,A12) -> 1
A13: 12 | B13: 3 | C13: 17 | D13: 45942 | E13: Online | F13: Net Banking | G13: Delivered | H13: =INDEX(Customers!$I$2:$I$901,MATCH(B13,Customers!$A$2:$A$901,0)) -> Regular | I13: =INDEX(Customers!$G$2:$G$901,MATCH(B13,Customers!$A$2:$A$901,0)) -> North | J13: =INDEX(Stores!$D$2:$D$18,MATCH(C13,Stores!$A$2:$A$18,0)) -> Online | K13: =SUMIF(OrderItems!$B$2:$B$6683,A13,OrderItems!$J$2:$J$6683) -> 1839 | L13: =SUMIF(OrderItems!$B$2:$B$6683,A13,OrderItems!$K$2:$K$6683) -> 1131.05 | M13: =K13-L13 -> 707.95 | N13: =COUNTIF(OrderItems!$B$2:$B$6683,A13) -> 1
... A3525: 3524 | B3525: 900 | C3525: 17 | D3525: 45616 | E3525: Online | F3525: UPI | G3525: Delivered | H3525: =INDEX(Customers!$I$2:$I$901,MATCH(B3525,Customers!$A$2:$A$901,0)) -> New | I3525: =INDEX(Customers!$G$2:$G$901,MATCH(B3525,Customers!$A$2:$A$901,0)) -> East | J3525: =INDEX(Stores!$D$2:$D$18,MATCH(C3525,Stores!$A$2:$A$18,0)) -> Online | K3525: =SUMIF(OrderItems!$B$2:$B$6683,A3525,OrderItems!$J$2:$J$6683) -> 3789.55 | L3525: =SUMIF(OrderItems!$B$2:$B$6683,A3525,OrderItems!$K$2:$K$6683) -> 2305.24 | M3525: =K3525-L3525 -> 1484.31 | N3525: =COUNTIF(OrderItems!$B$2:$B$6683,A3525) -> 1
